# **Error Handling with Async Functions in Express.js**

When using **`async`/`await`** in Express.js, handling errors efficiently is crucial for ensuring the smooth functioning of your application and providing meaningful error messages to users. Since `async` functions return promises, errors inside these functions are thrown as rejected promises. If not properly handled, these unhandled errors can crash your server.

This guide explains how to handle errors with `async` functions in Express.js, including common practices and solutions for catching errors and sending appropriate responses.

---

## **1. The Basics of async/await Error Handling**

### **Error in async functions**

- An error inside an `async` function is typically thrown as a promise rejection.
- To handle these errors, you need to use a `try/catch` block inside the route handler to catch any exceptions that occur during the execution of the `async` function.
- If an error occurs, it can be caught in the `catch` block, allowing you to send a relevant response to the client.

### Example:

```javascript
const express = require('express');
const app = express();

// Simulating an asynchronous function
function getUserData(userId) {
  return new Promise((resolve, reject) => {
    if (userId !== 1) {
      reject('User not found');
    } else {
      resolve({ id: 1, name: 'Alice' });
    }
  });
}

app.get('/user/:id', async (req, res) => {
  const userId = parseInt(req.params.id, 10);

  try {
    const user = await getUserData(userId); // Await the promise to resolve
    res.json(user); // Send the response if successful
  } catch (error) {
    res.status(404).send(error); // Send error message if promise is rejected
  }
});

app.listen(3000, () => {
  console.log('Server is running on http://localhost:3000');
});
```

- **`try` block**: The `await` expression is used to wait for the promise to resolve. If the promise is rejected, the control will jump to the `catch` block.
- **`catch` block**: Any error that occurs is caught here, and an appropriate response (`404` in this case) is sent to the client.

---

## **2. Express.js Error Handling Middleware**

Express provides a built-in mechanism for centralized error handling through **error-handling middleware**. This is particularly useful for handling unexpected errors in your application. The error-handling middleware in Express takes four arguments: `err`, `req`, `res`, and `next`. If an error is passed to `next()`, it will be caught by this middleware.

### **Error Handling Middleware Structure**

```javascript
// Error-handling middleware (placed after all other routes)
app.use((err, req, res, next) => {
  console.error(err.stack); // Log the error stack for debugging
  res.status(500).send('Something went wrong!'); // Send a generic error message
});
```

### **Using Async Function with Error Handling Middleware**

You can integrate `async` functions in Express with error-handling middleware by using a wrapper function. Here's an example of how you can create a wrapper to catch asynchronous errors and pass them to the error-handling middleware.

---

## **3. Wrapping Async Functions with Error Handling Middleware**

### **Step 1: Create a Utility for Wrapping Async Route Handlers**

```javascript
// Helper function to catch async errors
function asyncHandler(fn) {
  return function (req, res, next) {
    Promise.resolve(fn(req, res, next)).catch(next);
  };
}
```

- **Explanation**: The `asyncHandler` function is a utility that wraps `async` route handlers and catches any errors that occur within them. If any promise is rejected, it automatically passes the error to the Express error-handling middleware.

### **Step 2: Use asyncHandler with Route Handlers**

```javascript
const express = require('express');
const app = express();

// Simulate an asynchronous function (e.g., fetching data from a database)
function getUserData(userId) {
  return new Promise((resolve, reject) => {
    if (userId !== 1) {
      reject('User not found');
    } else {
      resolve({ id: 1, name: 'Alice' });
    }
  });
}

// Async route handler wrapped with asyncHandler
app.get('/user/:id', asyncHandler(async (req, res) => {
  const userId = parseInt(req.params.id, 10);
  const user = await getUserData(userId);
  res.json(user); // Send the user data as a JSON response
}));

// Error-handling middleware (to handle all errors in the app)
app.use((err, req, res, next) => {
  console.error(err.stack); // Log the error for debugging
  res.status(500).send({ error: err.message }); // Send error response to the client
});

app.listen(3000, () => {
  console.log('Server is running on http://localhost:3000');
});
```

### **Explanation**:
- **`asyncHandler` utility**: It wraps the asynchronous function, catching any errors and passing them to the error-handling middleware (`next()`).
- **Error-handling middleware**: The middleware catches errors thrown by the `async` functions or other parts of the app. The error is logged, and a response with a `500` status code and error message is sent.

---

## **4. Handling Specific Errors**

You can also handle specific errors and respond with appropriate status codes and messages. For example, you might want to send a `404` status if a resource is not found or a `400` status for a bad request.

### Example: Handling Specific Errors

```javascript
app.get('/user/:id', asyncHandler(async (req, res) => {
  const userId = parseInt(req.params.id, 10);

  if (isNaN(userId)) {
    throw new Error('Invalid user ID');
  }

  const user = await getUserData(userId);
  if (!user) {
    throw new Error('User not found');
  }

  res.json(user);
}));

// Custom error-handling middleware
app.use((err, req, res, next) => {
  if (err.message === 'Invalid user ID') {
    res.status(400).send('Bad Request: Invalid user ID');
  } else if (err.message === 'User not found') {
    res.status(404).send('User not found');
  } else {
    res.status(500).send('Internal Server Error');
  }
});
```

In this case:
- If the `userId` is invalid (not a number), the error will be caught and a `400 Bad Request` status will be sent.
- If no user is found, a `404 Not Found` status will be returned.
- Other unexpected errors will trigger a `500 Internal Server Error` status.

---

## **5. Catching Unhandled Promise Rejections Globally**

While handling errors inside `async` functions is important, you can also catch any unhandled promise rejections globally in the Node.js process. This is helpful for catching errors in async operations that might not be wrapped inside route handlers.

```javascript
process.on('unhandledRejection', (reason, promise) => {
  console.error('Unhandled promise rejection:', reason);
  // Optionally exit the process
  process.exit(1); // Exit the process if necessary
});
```

This ensures that unhandled promise rejections do not cause the application to silently fail. You can log the error and decide whether to exit the process.

---

## **6. Summary of Error Handling with async/await in Express**

- **`try/catch`**: Use `try/catch` blocks inside `async` route handlers to catch errors and send appropriate responses.
- **`asyncHandler`**: Use a helper function like `asyncHandler` to wrap `async` route handlers, automatically passing any errors to the error-handling middleware.
- **Error Handling Middleware**: Create custom error-handling middleware to catch all errors in the application and send relevant status codes and messages.
- **Global Error Handling**: Catch unhandled promise rejections globally to prevent unexpected crashes.
- **Specific Error Handling**: You can customize responses for different error scenarios (e.g., 400 for invalid input, 404 for missing resources).

By using these patterns and techniques, you can ensure that errors in asynchronous operations are properly handled, leading to a more stable and predictable Express application.